<?xml version="1.0"?>
<robot name="my_robot">

    <!-- Base Link -->
    <link name="base_link">
        <visual>
            <geometry>
                <box size="0.4 0.4 0.4"/>
            </geometry>
            <material name="blue">
                <color rgba="0 0 1 1"/>
            </material>
        </visual>
    </link>

    <!-- Left Wheel -->
    <link name="left_wheel">
        <visual>
            <geometry>
                <cylinder radius="0.1016" length="0.05"/>
            </geometry>
            <material name="black">
                <color rgba="0 0 0 1"/>
            </material>
        </visual>
    </link>

    <!-- Right Wheel -->
    <link name="right_wheel">
        <visual>
            <geometry>
                <cylinder radius="0.1016" length="0.05"/>
            </geometry>
            <material name="black">
                <color rgba="0 0 0 1"/>
            </material>
        </visual>
    </link>

    <!-- LiDAR -->
    <link name="lidar">
        <visual>
            <geometry>
                <cylinder radius="0.05" length="0.1"/>
            </geometry>
            <material name="gray">
                <color rgba="0.5 0.5 0.5 1"/>
            </material>
        </visual>
    </link>

    <!-- IMU -->
    <link name="imu">
        <visual>
            <geometry>
                <box size="0.05 0.05 0.05"/>
            </geometry>
            <material name="red">
                <color rgba="1 0 0 1"/>
            </material>
        </visual>
    </link>

    <!-- Joints -->
    <joint name="left_wheel_joint" type="continuous">
        <parent link="base_link"/>
        <child link="left_wheel"/>
        <origin xyz="-0.2 0 0" rpy="0 1.57 0"/>
        <axis xyz="0 1 0"/>
    </joint>

    <joint name="right_wheel_joint" type="continuous">
        <parent link="base_link"/>
        <child link="right_wheel"/>
        <origin xyz="0.2 0 0" rpy="0 1.57 0"/>
        <axis xyz="0 1 0"/>
    </joint>

    <joint name="lidar_joint" type="fixed">
        <parent link="base_link"/>
        <child link="lidar"/>
        <origin xyz="0 0 0.2" rpy="0 0 0"/>
    </joint>

    <joint name="imu_joint" type="fixed">
        <parent link="base_link"/>
        <child link="imu"/>
        <origin xyz="0 0 0" rpy="0 0 0"/>
    </joint>
</robot>
